<?xml version="1.0" ?>
<robot name="Stacker" xmlns:xacro="http://www.ros.org/wiki/xacro">
  <material name="Black">
    <color rgba="0 0 0 1" />
  </material>
  <material name="Grey">
    <color rgba="0.8 0.8 0.8 1" />
  </material>
  <material name="Orange">
    <color rgba="1 0.6 0 1" />
  </material>
  <material name="White">
    <color rgba="1 1 1 1" />
  </material>

  <link name="base_footprint"/> 

  <link name="base_link">
      <inertial>
      <!-- <origin xyz="0.0 -0.05460469962339392 0.6911432734922607" rpy="0 0 0"/> -->
      <!-- <origin xyz="0 -0.4 0.7" rpy="0 0 0"/> -->
      <origin xyz="0 0 0.7" rpy="0 0 0"/>
      <mass value="200"/>
      <inertia ixx="35.33333333333333" iyy="43.33333333333333" izz="13.3" ixy="0.0" iyz="0" ixz="0.0"/>
      </inertial>

      <visual>
          <origin xyz="0 0 0.7" rpy="0 0 0" />
          <geometry>
            <box size="0.8 0.4 1.4" />
          </geometry>
          <material name="Orange" />
      </visual>

      <collision>
        <origin xyz="0 0 0.7" rpy="0 0 0" />
        <geometry>
          <box size="0.8 0.4 1.4" />
        </geometry>
      </collision>
  </link>


  	
<!-- 
  <link name="imu_link">
    <visual>
      <geometry>
        <box size="0.05 0.05 0.05"/>
      </geometry>
    </visual>

    <collision>
      <geometry>
        <box size="0.05 0.05 0.05"/>
      </geometry>
    </collision>

    <inertial>
      <mass value="1e-5" />
      <origin xyz="0 0 0" rpy="0 0 0"/>
      <inertia ixx="1e-6" ixy="0" ixz="0" iyy="1e-6" iyz="0" izz="1e-6" />
    </inertial>
  </link>

   <gazebo reference="imu_link">
      <sensor name="imu_sensor" type="imu">
      <plugin filename="libgazebo_ros_imu_sensor.so" name="imu_plugin">
          <ros>
            <namespace>/</namespace>
            <remapping>~/out:=imu</remapping>
          </ros>
          <initial_orientation_as_reference>false</initial_orientation_as_reference>
        </plugin>
        <always_on>true</always_on>
        <update_rate>100</update_rate>
        <visualize>true</visualize>
        <imu>
          <angular_velocity>
            <x>
              <noise type="gaussian">
                <mean>0.0</mean>
                <stddev>2e-4</stddev>
                <bias_mean>0.0000075</bias_mean>
                <bias_stddev>0.0000008</bias_stddev>
              </noise>
            </x>
            <y>
              <noise type="gaussian">
                <mean>0.0</mean>
                <stddev>2e-4</stddev>
                <bias_mean>0.0000075</bias_mean>
                <bias_stddev>0.0000008</bias_stddev>
              </noise>
            </y>
            <z>
              <noise type="gaussian">
                <mean>0.0</mean>
                <stddev>2e-4</stddev>
                <bias_mean>0.0000075</bias_mean>
                <bias_stddev>0.0000008</bias_stddev>
              </noise>
            </z>
          </angular_velocity>
          <linear_acceleration>
            <x>
              <noise type="gaussian">
                <mean>0.0</mean>
                <stddev>1.7e-2</stddev>
                <bias_mean>0.1</bias_mean>
                <bias_stddev>0.001</bias_stddev>
              </noise>
            </x>
            <y>
              <noise type="gaussian">
                <mean>0.0</mean>
                <stddev>1.7e-2</stddev>
                <bias_mean>0.1</bias_mean>
                <bias_stddev>0.001</bias_stddev>
              </noise>
            </y>
            <z>
              <noise type="gaussian">
                <mean>0.0</mean>
                <stddev>1.7e-2</stddev>
                <bias_mean>0.1</bias_mean>
                <bias_stddev>0.001</bias_stddev>
              </noise>
            </z>
          </linear_acceleration>
        </imu>
      </sensor>
    </gazebo> -->

  <link name = "laser_link">
      <visual>
        <geometry>
          <box size="0.05 0.05 0.05"/>
        </geometry>
        <material name = "White" />
      </visual>

      <collision>
        <geometry>
          <box size="0.05 0.05 0.05"/>
        </geometry>
      </collision>  

      <inertial>
      <mass value="1e-5" />
      <origin xyz="0 0 0" rpy="0 0 0"/>
      <inertia ixx="1e-6" ixy="0" ixz="0" iyy="1e-6" iyz="0" izz="1e-6" />
    </inertial>
  </link>


  <gazebo reference="laser_link">
    <sensor type="ray" name="laser_scanner">
    <always_on>true</always_on>
    <visualize>true</visualize>
    <update_rate>30</update_rate>
    <ray>
      <scan>
        <horizontal>
          <samples>360</samples>
          <resolution>1</resolution>
          <min_angle>-1.57</min_angle>
          <max_angle>1.57</max_angle>
        </horizontal>
      </scan>
      <range>
        <min>0.30</min>
        <max>25.0</max>
        <resolution>0.1</resolution>
      </range>
    </ray>
      <plugin name="scan" filename="libgazebo_ros_ray_sensor.so">
        <ros>
          <remapping>~/out:=scan</remapping>
        </ros>
        <output_type>sensor_msgs/LaserScan</output_type>
        <frame_name>laser_link</frame_name>
      </plugin>
    </sensor>
  </gazebo>

  <link name="wheel_1">
    <inertial>
      <!-- <origin xyz="0.06 1.459363100219793e-17 1.3877787807814457e-17" rpy="0 0 0"/> -->
      <origin xyz="0.0 0.0 0.0" rpy="0 0 0"/>
      <mass value="30"/>
      <inertia ixx="0.1991875" iyy="0.1991875" izz="0.198375" ixy="0.0" iyz="0.0" ixz="0.0"/>
    </inertial>
    <visual>
      
      <geometry>
        <sphere  radius = "0.115"/>
      </geometry>
      <material name="Grey"/>
    </visual>
    <collision>
      
      <geometry>
        <cylinder length="0.2" radius = "0.115"/>
      </geometry>
    </collision>
  </link>

  <link name="steering_joint_1">
    <inertial>
      <origin xyz="0 0 0" rpy="0 0 0"/>
      <mass value="0.005"/>
      <inertia ixx="0.1" iyy="0.1" izz="0.1" ixy="0.0" iyz="0.0" ixz="0.0"/>
    </inertial>
    <visual>
      <origin xyz="-0.0 -0.0 0" rpy="0 0 0"/>
      <geometry>
        <box size="0.01 0.01 0.01" />
      </geometry>
      <material name="Black"/>
    </visual>
    
  </link>

  <link name="left_fork">
    <collision>
        <!-- <origin xyz="0 -0.45 0.03" rpy="0 0 0" /> -->
        <geometry>
          <box size="0.16 0.9 0.06" />
        </geometry>
    </collision>

      <visual>
        <!-- <origin xyz="0 -0.45 0.03" rpy="0 0 0" /> -->
        <geometry>
          <box size="0.16 0.9 0.06" />
        </geometry>
        <material name="Black" />
      </visual>

      <inertial>
        
        <mass value="30" />
        <inertia ixx="2.0340000000000003" ixy="0.073" ixz="2.089" iyy="0.0" iyz="0.0" izz="0.0" />
      </inertial>

  </link>

  <link name="right_fork">
    <collision>
        <!-- <origin xyz="0 -0.45 0.03" rpy="0 0 0" /> -->
        <geometry>
          <box size="0.16 0.9 0.06" />
        </geometry>
      </collision>

      <visual>
        <!-- <origin xyz="0 -0.45 0.03" rpy="0 0 0" /> -->
        <geometry>
          <box size="0.16 0.9 0.06" />
        </geometry>
        <material name="Black" />
      </visual>

    <inertial>
        
        <mass value="30" />
        <inertia ixx="2.0340000000000003" ixy="0.073" ixz="2.089" iyy="0.0" iyz="0.0" izz="0.0" />
      </inertial>

  </link>

  <link name = "fox_wheel_R">
    <inertial>
      <mass value="1" />
      <inertia ixx="0.0006895833333333334" ixy="0.0" ixz="0.0" iyy="0.0006895833333333334" iyz="0.0" izz="0.00031250000000000006" />
    </inertial>

    <visual>
      <geometry>
        <cylinder length="0.08" radius="0.025" />
      </geometry>
      <material name="Grey" />
    </visual>

    <collision>
      <geometry>
        <cylinder length="0.08" radius="0.025" />
      </geometry>
    </collision>

  </link>
  
  <link name = "fox_wheel_L">
    <inertial>
      <mass value="1" />
      <inertia ixx="0.0006895833333333334" ixy="0.0" ixz="0.0" iyy="0.0006895833333333334" iyz="0.0" izz="0.00031250000000000006" />
    </inertial>

    <visual>
      <geometry>
        <cylinder length="0.08" radius="0.025" />
      </geometry>
      <material name="Grey" />
    </visual>

    <collision>
      <geometry>
        <cylinder length="0.08" radius="0.025" />
      </geometry>
    </collision>

  </link>

  <joint name="base_link_joint" type="fixed">
      <parent link="base_footprint"/>
      <child link="base_link"/>
      <origin rpy="0 0 -1.57" xyz="0 0 0"/>
  </joint>

  <joint name="left_fork_joint" type="fixed">
      <parent link="base_link"/>
      <child link="left_fork"/>
      <origin rpy="0 0 0" xyz="-0.156458 -0.65 0.03 "/>
  </joint>

  <joint name="right_fork_joint" type="fixed">
    <parent link="base_link"/>
    <child link="right_fork"/>
    <origin rpy="0 0 0" xyz="0.156458 -0.65 0.03"/>
  </joint>

  <joint name="steering_joint" type="revolute">
    <limit lower="-1.57" upper="1.57" effort="10" velocity="1"/>
    <origin xyz="0.0 0.0 0.09" rpy="0 0 0"/>
    <!-- <origin xyz="0.0 0.0 0.0" rpy="0 0 0"/> -->
    <dynamics damping="10" friction="0.0"/>
    <parent link="base_link"/>
    <child link="steering_joint_1"/>
    <axis xyz="0.0 0.0 1.0"/>
  </joint>

  <joint name="fork_wheel_r_joint" type="continuous">
    <origin xyz="0 -0.22 -0.0225" rpy="-1.57 0 -1.57"/>
    <parent link="right_fork"/>
    <child link="fox_wheel_R"/>
    <axis xyz="0.0 0.0 -1.0"/>
  </joint>

  <joint name="fork_wheel_l_joint" type="continuous">
    <origin xyz="0 -0.22 -0.0225" rpy="-1.57 0 -1.57"/>
    <parent link="left_fork"/>
    <child link="fox_wheel_L"/>
    <axis xyz="0.0 0.0 -1.0"/>
  </joint>

  <joint name="traction_joint" type="continuous">
    <limit  effort="50" velocity="0.5"/>
    <origin xyz="-0.0 0.0 -0.0" rpy="-1.57 0 -1.57"/>
    <parent link="steering_joint_1"/>
    <child link="wheel_1"/>
    <axis xyz="0.0 0.0 -1.0"/>
    <dynamics damping="2" friction="1.0"/>
  </joint>

  <joint name="laser_joint" type="fixed">
    <axis xyz = "0 1 0"/>
    <origin xyz="0 0.225 0.05" rpy = "0 0 1.57"/>
    <parent link="base_link"/>
    <child link="laser_link"/>
  </joint>

  <!-- <joint name="imu_joint" type="fixed">
    <parent link="base_link"/>
    <child link="imu_link"/>
    <origin xyz="0 0 0.01"/>
  </joint> -->


  <ros2_control name="GazeboSystem" type="system">
    <hardware>
      <plugin>gazebo_ros2_control/GazeboSystem</plugin>
    </hardware>
    <joint name="steering_joint">
      <command_interface name="position" />
      <state_interface name="position" />
    </joint>
    <joint name="traction_joint">
      <command_interface name="velocity" />
      <state_interface name="velocity" />
      <state_interface name="position" />
    </joint>
  </ros2_control>
<!-- 
  <gazebo>
    <plugin filename="libgazebo_ros2_control.so" name="gazebo_ros2_control">
      <parameters>$(find stacker_description)/config/stacker_drive_controller.yaml</parameters>
    </plugin>
  </gazebo> -->
  <gazebo reference="base_link">
     <material>Gazebo/Orange</material>
     <gravity>True</gravity>
  </gazebo>

   <gazebo reference="left_fork">
     <material>Gazebo/Black</material>
     <gravity>True</gravity>
  </gazebo>

  <gazebo reference="right_fork">
     <material>Gazebo/Black</material>
     <gravity>True</gravity>
  </gazebo>

  <gazebo reference="fox_wheel_R">
     <material>Gazebo/Grey</material>
     <gravity>True</gravity>
     <mu1>10000.0</mu1>
     <mu2>10000.0</mu2>
      <kp>500000.0</kp>
      <kd>10.0</kd>
      <minDepth>0.001</minDepth>
      <maxVel>0.1</maxVel>
      <fdir1>1 0 0</fdir1>
  </gazebo>

  <gazebo reference="fox_wheel_L">
     <material>Gazebo/Grey</material>
     <gravity>True</gravity>
     <mu1>10000.0</mu1>
     <mu2>10000.0</mu2>
      <kp>500000.0</kp>
      <kd>10.0</kd>
      <minDepth>0.001</minDepth>
      <maxVel>0.1</maxVel>
      <fdir1>1 0 0</fdir1>
  </gazebo>

  <gazebo reference="wheel_1">
     <material>Gazebo/Grey</material>
     <gravity>True</gravity>
     <mu1>10000.0</mu1>
     <mu2>10000.0</mu2>
      <kp>500000.0</kp>
      <kd>10.0</kd>
      <minDepth>0.001</minDepth>
      <maxVel>0.1</maxVel>
      <fdir1>1 0 0</fdir1>
  </gazebo>


    <gazebo>
      <plugin filename="libgazebo_ros2_control.so" name="gazebo_ros2_control">
        <ros>
            <!-- <namespace>/</namespace> -->
          <remapping>/tricycle_controller/cmd_vel:=/cmd_vel</remapping>
          <remapping>/tricycle_controller/odom:=/odom</remapping>
        </ros>
        <parameters>$(find stacker_description)/config/stacker_drive_controller.yaml</parameters>
      </plugin>
    </gazebo>




  

</robot>
